2013-01-03 14:37:33
Traceback (most recent call last):
  File "./sublimesvn/threads.py", line 18, in run_with_except_hook
  File "./sublimesvn/proc.py", line 88, in run
ProcessError: <unprintable ProcessError object>
2013-01-03 14:37:50
Traceback (most recent call last):
  File "./sublimesvn/threads.py", line 18, in run_with_except_hook
  File "./sublimesvn/proc.py", line 88, in run
ProcessError: <unprintable ProcessError object>
2013-01-11 16:56:04
Traceback (most recent call last):
  File "./sublimesvn/threads.py", line 18, in run_with_except_hook
  File "./sublimesvn/proc.py", line 88, in run
ProcessError: <unprintable ProcessError object>
2013-01-16 11:08:05
Traceback (most recent call last):
  File "./sublimesvn/threads.py", line 18, in run_with_except_hook
  File "./sublimesvn/threads.py", line 89, in run
  File "./sublimesvn/commands.py", line 1149, in do_edit_message
  File ".\os.py", line 157, in makedirs
WindowsError: [Error 183] Impossible de créer un fichier déjà existant: 'c:\\users\\stepha~1.vas\\appdata\\local\\temp\\sublime-svn-1358352485'
2013-01-16 14:38:54
Traceback (most recent call last):
  File "./sublimesvn/threads.py", line 18, in run_with_except_hook
  File "./sublimesvn/listeners.py", line 30, in run
  File "./sublimesvn/proc.py", line 71, in get_wc_root
  File "./sublimesvn/proc.py", line 172, in find_wc_root
ProcessError
2013-01-16 14:40:40
Traceback (most recent call last):
  File "./sublimesvn/threads.py", line 18, in run_with_except_hook
  File "./sublimesvn/proc.py", line 88, in run
ProcessError: <unprintable ProcessError object>
2013-01-16 14:40:46
Traceback (most recent call last):
  File "./sublimesvn/threads.py", line 18, in run_with_except_hook
  File "./sublimesvn/listeners.py", line 30, in run
  File "./sublimesvn/proc.py", line 71, in get_wc_root
  File "./sublimesvn/proc.py", line 172, in find_wc_root
ProcessError: <unprintable ProcessError object>
2013-01-16 14:41:11
Traceback (most recent call last):
  File "./sublimesvn/threads.py", line 18, in run_with_except_hook
  File "./sublimesvn/proc.py", line 88, in run
ProcessError: <unprintable ProcessError object>
2013-01-16 18:59:09
Traceback (most recent call last):
  File "./sublimesvn/threads.py", line 18, in run_with_except_hook
  File "./sublimesvn/listeners.py", line 30, in run
  File "./sublimesvn/proc.py", line 71, in get_wc_root
  File "./sublimesvn/proc.py", line 172, in find_wc_root
ProcessError
2013-01-17 16:38:12
Traceback (most recent call last):
  File "./sublimesvn/threads.py", line 18, in run_with_except_hook
  File "./sublimesvn/proc.py", line 88, in run
ProcessError: <unprintable ProcessError object>
2013-01-17 16:38:12
Traceback (most recent call last):
  File "./sublimesvn/threads.py", line 18, in run_with_except_hook
  File "./sublimesvn/listeners.py", line 30, in run
  File "./sublimesvn/proc.py", line 71, in get_wc_root
  File "./sublimesvn/proc.py", line 172, in find_wc_root
ProcessError: <unprintable ProcessError object>
2013-01-18 11:37:25
Traceback (most recent call last):
  File "./sublimesvn/threads.py", line 18, in run_with_except_hook
  File "./sublimesvn/listeners.py", line 30, in run
  File "./sublimesvn/proc.py", line 71, in get_wc_root
  File "./sublimesvn/proc.py", line 172, in find_wc_root
ProcessError
2013-01-18 11:37:25
Traceback (most recent call last):
  File "./sublimesvn/threads.py", line 18, in run_with_except_hook
  File "./sublimesvn/listeners.py", line 30, in run
  File "./sublimesvn/proc.py", line 71, in get_wc_root
  File "./sublimesvn/proc.py", line 172, in find_wc_root
ProcessError
2013-01-18 11:37:25
Traceback (most recent call last):
  File "./sublimesvn/threads.py", line 18, in run_with_except_hook
  File "./sublimesvn/listeners.py", line 30, in run
  File "./sublimesvn/proc.py", line 71, in get_wc_root
  File "./sublimesvn/proc.py", line 172, in find_wc_root
ProcessError
2013-01-18 11:37:25
Traceback (most recent call last):
  File "./sublimesvn/threads.py", line 18, in run_with_except_hook
  File "./sublimesvn/listeners.py", line 30, in run
  File "./sublimesvn/proc.py", line 71, in get_wc_root
  File "./sublimesvn/proc.py", line 172, in find_wc_root
ProcessError
2013-01-18 11:37:25
Traceback (most recent call last):
  File "./sublimesvn/threads.py", line 18, in run_with_except_hook
  File "./sublimesvn/listeners.py", line 30, in run
  File "./sublimesvn/proc.py", line 71, in get_wc_root
  File "./sublimesvn/proc.py", line 172, in find_wc_root
ProcessError
2013-01-18 11:37:43
Traceback (most recent call last):
  File "./sublimesvn/threads.py", line 18, in run_with_except_hook
  File "./sublimesvn/listeners.py", line 30, in run
  File "./sublimesvn/proc.py", line 71, in get_wc_root
  File "./sublimesvn/proc.py", line 172, in find_wc_root
ProcessError
2013-01-18 11:37:54
Traceback (most recent call last):
  File "./sublimesvn/threads.py", line 18, in run_with_except_hook
  File "./sublimesvn/listeners.py", line 30, in run
  File "./sublimesvn/proc.py", line 71, in get_wc_root
  File "./sublimesvn/proc.py", line 172, in find_wc_root
ProcessError
2013-01-18 11:37:54
Traceback (most recent call last):
  File "./sublimesvn/threads.py", line 18, in run_with_except_hook
  File "./sublimesvn/listeners.py", line 30, in run
  File "./sublimesvn/proc.py", line 71, in get_wc_root
  File "./sublimesvn/proc.py", line 172, in find_wc_root
ProcessError
2013-01-18 11:38:05
Traceback (most recent call last):
  File "./sublimesvn/threads.py", line 18, in run_with_except_hook
  File "./sublimesvn/listeners.py", line 30, in run
  File "./sublimesvn/proc.py", line 71, in get_wc_root
  File "./sublimesvn/proc.py", line 172, in find_wc_root
ProcessError
2013-01-18 11:39:06
Traceback (most recent call last):
  File "./sublimesvn/threads.py", line 18, in run_with_except_hook
  File "./sublimesvn/listeners.py", line 30, in run
  File "./sublimesvn/proc.py", line 71, in get_wc_root
  File "./sublimesvn/proc.py", line 172, in find_wc_root
ProcessError
2013-01-18 11:39:17
Traceback (most recent call last):
  File "./sublimesvn/threads.py", line 18, in run_with_except_hook
  File "./sublimesvn/listeners.py", line 30, in run
  File "./sublimesvn/proc.py", line 71, in get_wc_root
  File "./sublimesvn/proc.py", line 172, in find_wc_root
ProcessError
2013-01-18 11:39:31
Traceback (most recent call last):
  File "./sublimesvn/threads.py", line 18, in run_with_except_hook
  File "./sublimesvn/listeners.py", line 30, in run
  File "./sublimesvn/proc.py", line 71, in get_wc_root
  File "./sublimesvn/proc.py", line 172, in find_wc_root
ProcessError
2013-01-18 11:39:43
Traceback (most recent call last):
  File "./sublimesvn/threads.py", line 18, in run_with_except_hook
  File "./sublimesvn/listeners.py", line 30, in run
  File "./sublimesvn/proc.py", line 71, in get_wc_root
  File "./sublimesvn/proc.py", line 172, in find_wc_root
ProcessError
2013-01-18 11:39:45
Traceback (most recent call last):
  File "./sublimesvn/threads.py", line 18, in run_with_except_hook
  File "./sublimesvn/listeners.py", line 30, in run
  File "./sublimesvn/proc.py", line 71, in get_wc_root
  File "./sublimesvn/proc.py", line 172, in find_wc_root
ProcessError: <unprintable ProcessError object>
2013-01-18 11:39:54
Traceback (most recent call last):
  File "./sublimesvn/threads.py", line 18, in run_with_except_hook
  File "./sublimesvn/listeners.py", line 30, in run
  File "./sublimesvn/proc.py", line 71, in get_wc_root
  File "./sublimesvn/proc.py", line 172, in find_wc_root
ProcessError
2013-01-18 11:40:05
Traceback (most recent call last):
  File "./sublimesvn/threads.py", line 18, in run_with_except_hook
  File "./sublimesvn/listeners.py", line 30, in run
  File "./sublimesvn/proc.py", line 71, in get_wc_root
  File "./sublimesvn/proc.py", line 172, in find_wc_root
ProcessError
2013-01-18 11:40:11
Traceback (most recent call last):
  File "./sublimesvn/threads.py", line 18, in run_with_except_hook
  File "./sublimesvn/listeners.py", line 30, in run
  File "./sublimesvn/proc.py", line 71, in get_wc_root
  File "./sublimesvn/proc.py", line 172, in find_wc_root
ProcessError
2013-01-18 11:40:16
Traceback (most recent call last):
  File "./sublimesvn/threads.py", line 18, in run_with_except_hook
  File "./sublimesvn/listeners.py", line 30, in run
  File "./sublimesvn/proc.py", line 71, in get_wc_root
  File "./sublimesvn/proc.py", line 172, in find_wc_root
ProcessError
2013-01-18 11:43:14
Traceback (most recent call last):
  File "./sublimesvn/threads.py", line 18, in run_with_except_hook
  File "./sublimesvn/listeners.py", line 30, in run
  File "./sublimesvn/proc.py", line 71, in get_wc_root
  File "./sublimesvn/proc.py", line 172, in find_wc_root
ProcessError
2013-01-18 11:43:18
Traceback (most recent call last):
  File "./sublimesvn/threads.py", line 18, in run_with_except_hook
  File "./sublimesvn/listeners.py", line 30, in run
  File "./sublimesvn/proc.py", line 71, in get_wc_root
  File "./sublimesvn/proc.py", line 172, in find_wc_root
ProcessError
2013-01-18 19:03:54
Traceback (most recent call last):
  File "./sublimesvn/threads.py", line 18, in run_with_except_hook
  File "./sublimesvn/listeners.py", line 30, in run
  File "./sublimesvn/proc.py", line 71, in get_wc_root
  File "./sublimesvn/proc.py", line 172, in find_wc_root
ProcessError: <unprintable ProcessError object>
2013-01-18 19:04:04
Traceback (most recent call last):
  File "./sublimesvn/threads.py", line 18, in run_with_except_hook
  File "./sublimesvn/proc.py", line 88, in run
ProcessError: <unprintable ProcessError object>
2013-01-21 11:16:09
Traceback (most recent call last):
  File "./sublimesvn/threads.py", line 18, in run_with_except_hook
  File "./sublimesvn/proc.py", line 88, in run
KeyError: u'W:\\current_trunk\\trunk\\src'
2013-01-21 11:16:11
Traceback (most recent call last):
  File "./sublimesvn/threads.py", line 18, in run_with_except_hook
  File "./sublimesvn/listeners.py", line 30, in run
  File "./sublimesvn/proc.py", line 71, in get_wc_root
  File "./sublimesvn/proc.py", line 113, in find_wc_root
KeyError: u'W:\\current_trunk\\trunk\\src'
2013-01-21 11:16:11
Traceback (most recent call last):
  File "./sublimesvn/threads.py", line 18, in run_with_except_hook
  File "./sublimesvn/proc.py", line 88, in run
KeyError: u'W:\\current_trunk\\trunk\\src'
2013-01-21 11:16:11
Traceback (most recent call last):
  File "./sublimesvn/threads.py", line 18, in run_with_except_hook
  File "./sublimesvn/proc.py", line 88, in run
KeyError: u'W:\\current_trunk\\trunk\\src'
2013-01-21 11:16:15
Traceback (most recent call last):
  File "./sublimesvn/threads.py", line 18, in run_with_except_hook
  File "./sublimesvn/listeners.py", line 30, in run
  File "./sublimesvn/proc.py", line 71, in get_wc_root
  File "./sublimesvn/proc.py", line 113, in find_wc_root
KeyError: u'W:\\current_trunk\\trunk\\src'
2013-01-21 11:16:18
Traceback (most recent call last):
  File "./sublimesvn/threads.py", line 18, in run_with_except_hook
  File "./sublimesvn/listeners.py", line 30, in run
  File "./sublimesvn/proc.py", line 71, in get_wc_root
  File "./sublimesvn/proc.py", line 113, in find_wc_root
KeyError: u'W:\\current_trunk\\trunk\\src'
2013-01-21 11:16:24
Traceback (most recent call last):
  File "./sublimesvn/threads.py", line 18, in run_with_except_hook
  File "./sublimesvn/listeners.py", line 30, in run
  File "./sublimesvn/proc.py", line 71, in get_wc_root
  File "./sublimesvn/proc.py", line 113, in find_wc_root
KeyError: u'W:\\current_trunk\\trunk\\src'
2013-01-23 20:21:11
Traceback (most recent call last):
  File "./sublimesvn/threads.py", line 18, in run_with_except_hook
  File "./sublimesvn/threads.py", line 89, in run
  File "./sublimesvn/listeners.py", line 247, in do_operation
  File ".\shutil.py", line 221, in rmtree
  File ".\shutil.py", line 219, in rmtree
WindowsError: [Error 2] Le fichier spécifié est introuvable: u'c:\\users\\stepha~1.vas\\appdata\\local\\temp\\sublime-svn-1358990416\\SVN'
2013-01-24 09:58:39
Traceback (most recent call last):
  File ".\sublime_plugin.py", line 190, in on_post_save
  File ".\sublime_plugin.py", line 154, in run_timed_function
  File ".\sublime_plugin.py", line 189, in <lambda>
  File "./sublimesvn/listeners.py", line 80, in on_post_save
AttributeError: 'NoneType' object has no attribute 'id'
2013-01-24 17:40:58
Traceback (most recent call last):
  File "./sublimesvn/threads.py", line 18, in run_with_except_hook
  File "./sublimesvn/listeners.py", line 30, in run
  File "./sublimesvn/proc.py", line 71, in get_wc_root
  File "./sublimesvn/proc.py", line 172, in find_wc_root
ProcessError: <unprintable ProcessError object>
2013-01-31 14:21:25
Traceback (most recent call last):
  File "./sublimesvn/threads.py", line 18, in run_with_except_hook
  File "./sublimesvn/listeners.py", line 30, in run
  File "./sublimesvn/proc.py", line 71, in get_wc_root
  File "./sublimesvn/proc.py", line 172, in find_wc_root
ProcessError: <unprintable ProcessError object>
2013-02-08 17:33:40
Traceback (most recent call last):
  File "./sublimesvn/threads.py", line 18, in run_with_except_hook
  File "./sublimesvn/listeners.py", line 30, in run
  File "./sublimesvn/proc.py", line 71, in get_wc_root
  File "./sublimesvn/proc.py", line 172, in find_wc_root
ProcessError: <unprintable ProcessError object>
2013-02-08 17:34:47
Traceback (most recent call last):
  File "./sublimesvn/threads.py", line 18, in run_with_except_hook
  File "./sublimesvn/listeners.py", line 30, in run
  File "./sublimesvn/proc.py", line 71, in get_wc_root
  File "./sublimesvn/proc.py", line 172, in find_wc_root
ProcessError: <unprintable ProcessError object>
2013-02-11 12:24:04
Traceback (most recent call last):
  File "./sublimesvn/threads.py", line 18, in run_with_except_hook
  File "./sublimesvn/listeners.py", line 30, in run
  File "./sublimesvn/proc.py", line 71, in get_wc_root
  File "./sublimesvn/proc.py", line 172, in find_wc_root
ProcessError: <unprintable ProcessError object>
2013-02-11 12:24:06
Traceback (most recent call last):
  File "./sublimesvn/threads.py", line 18, in run_with_except_hook
  File "./sublimesvn/listeners.py", line 30, in run
  File "./sublimesvn/proc.py", line 71, in get_wc_root
  File "./sublimesvn/proc.py", line 172, in find_wc_root
ProcessError
2013-02-11 12:24:06
Traceback (most recent call last):
  File "./sublimesvn/threads.py", line 18, in run_with_except_hook
  File "./sublimesvn/listeners.py", line 30, in run
  File "./sublimesvn/proc.py", line 71, in get_wc_root
  File "./sublimesvn/proc.py", line 172, in find_wc_root
ProcessError
2013-02-11 12:24:11
Traceback (most recent call last):
  File "./sublimesvn/threads.py", line 18, in run_with_except_hook
  File "./sublimesvn/listeners.py", line 30, in run
  File "./sublimesvn/proc.py", line 71, in get_wc_root
  File "./sublimesvn/proc.py", line 172, in find_wc_root
ProcessError: <unprintable ProcessError object>
2013-02-19 17:02:58
Traceback (most recent call last):
  File "./sublimesvn/threads.py", line 18, in run_with_except_hook
  File "./sublimesvn/listeners.py", line 30, in run
  File "./sublimesvn/proc.py", line 71, in get_wc_root
  File "./sublimesvn/proc.py", line 172, in find_wc_root
ProcessError
2013-02-19 17:39:28
Traceback (most recent call last):
  File "./sublimesvn/threads.py", line 18, in run_with_except_hook
  File "./sublimesvn/listeners.py", line 30, in run
  File "./sublimesvn/proc.py", line 71, in get_wc_root
  File "./sublimesvn/proc.py", line 172, in find_wc_root
ProcessError: <unprintable ProcessError object>
2013-02-19 17:39:28
Traceback (most recent call last):
  File "./sublimesvn/threads.py", line 18, in run_with_except_hook
  File "./sublimesvn/listeners.py", line 30, in run
  File "./sublimesvn/proc.py", line 71, in get_wc_root
  File "./sublimesvn/proc.py", line 172, in find_wc_root
ProcessError
2013-02-19 17:43:18
Traceback (most recent call last):
  File "./sublimesvn/threads.py", line 18, in run_with_except_hook
  File "./sublimesvn/listeners.py", line 30, in run
  File "./sublimesvn/proc.py", line 71, in get_wc_root
  File "./sublimesvn/proc.py", line 172, in find_wc_root
ProcessError: <unprintable ProcessError object>
2013-02-19 17:48:00
Traceback (most recent call last):
  File "./sublimesvn/threads.py", line 18, in run_with_except_hook
  File "./sublimesvn/listeners.py", line 30, in run
  File "./sublimesvn/proc.py", line 71, in get_wc_root
  File "./sublimesvn/proc.py", line 172, in find_wc_root
ProcessError
2013-02-19 17:50:38
Traceback (most recent call last):
  File "./sublimesvn/threads.py", line 18, in run_with_except_hook
  File "./sublimesvn/listeners.py", line 30, in run
  File "./sublimesvn/proc.py", line 71, in get_wc_root
  File "./sublimesvn/proc.py", line 172, in find_wc_root
ProcessError
2013-02-19 17:51:11
Traceback (most recent call last):
  File "./sublimesvn/threads.py", line 18, in run_with_except_hook
  File "./sublimesvn/listeners.py", line 30, in run
  File "./sublimesvn/proc.py", line 71, in get_wc_root
  File "./sublimesvn/proc.py", line 172, in find_wc_root
ProcessError: <unprintable ProcessError object>
2013-02-19 18:05:22
Traceback (most recent call last):
  File "./sublimesvn/threads.py", line 18, in run_with_except_hook
  File "./sublimesvn/listeners.py", line 30, in run
  File "./sublimesvn/proc.py", line 71, in get_wc_root
  File "./sublimesvn/proc.py", line 172, in find_wc_root
ProcessError
2013-02-19 18:05:35
Traceback (most recent call last):
  File "./sublimesvn/threads.py", line 18, in run_with_except_hook
  File "./sublimesvn/listeners.py", line 30, in run
  File "./sublimesvn/proc.py", line 71, in get_wc_root
  File "./sublimesvn/proc.py", line 172, in find_wc_root
ProcessError: <unprintable ProcessError object>
2013-02-19 18:07:00
Traceback (most recent call last):
  File "./sublimesvn/threads.py", line 18, in run_with_except_hook
  File "./sublimesvn/listeners.py", line 30, in run
  File "./sublimesvn/proc.py", line 71, in get_wc_root
  File "./sublimesvn/proc.py", line 172, in find_wc_root
ProcessError
2013-02-19 18:07:10
Traceback (most recent call last):
  File "./sublimesvn/threads.py", line 18, in run_with_except_hook
  File "./sublimesvn/listeners.py", line 30, in run
  File "./sublimesvn/proc.py", line 71, in get_wc_root
  File "./sublimesvn/proc.py", line 172, in find_wc_root
ProcessError
2013-02-19 18:07:19
Traceback (most recent call last):
  File "./sublimesvn/threads.py", line 18, in run_with_except_hook
  File "./sublimesvn/listeners.py", line 30, in run
  File "./sublimesvn/proc.py", line 71, in get_wc_root
  File "./sublimesvn/proc.py", line 172, in find_wc_root
ProcessError
2013-02-19 18:07:27
Traceback (most recent call last):
  File "./sublimesvn/threads.py", line 18, in run_with_except_hook
  File "./sublimesvn/listeners.py", line 30, in run
  File "./sublimesvn/proc.py", line 71, in get_wc_root
  File "./sublimesvn/proc.py", line 172, in find_wc_root
ProcessError
2013-02-19 18:07:35
Traceback (most recent call last):
  File "./sublimesvn/threads.py", line 18, in run_with_except_hook
  File "./sublimesvn/listeners.py", line 30, in run
  File "./sublimesvn/proc.py", line 71, in get_wc_root
  File "./sublimesvn/proc.py", line 172, in find_wc_root
ProcessError: <unprintable ProcessError object>
2013-02-19 18:07:42
Traceback (most recent call last):
  File "./sublimesvn/threads.py", line 18, in run_with_except_hook
  File "./sublimesvn/listeners.py", line 30, in run
  File "./sublimesvn/proc.py", line 71, in get_wc_root
  File "./sublimesvn/proc.py", line 172, in find_wc_root
ProcessError: <unprintable ProcessError object>
2013-02-19 18:10:37
Traceback (most recent call last):
  File "./sublimesvn/threads.py", line 18, in run_with_except_hook
  File "./sublimesvn/listeners.py", line 30, in run
  File "./sublimesvn/proc.py", line 71, in get_wc_root
  File "./sublimesvn/proc.py", line 172, in find_wc_root
ProcessError
2013-02-21 14:12:06
Traceback (most recent call last):
  File "./sublimesvn/threads.py", line 18, in run_with_except_hook
  File "./sublimesvn/listeners.py", line 30, in run
  File "./sublimesvn/proc.py", line 71, in get_wc_root
  File "./sublimesvn/proc.py", line 172, in find_wc_root
ProcessError: <unprintable ProcessError object>
2013-02-21 14:21:36
Traceback (most recent call last):
  File "./sublimesvn/threads.py", line 18, in run_with_except_hook
  File "./sublimesvn/listeners.py", line 30, in run
  File "./sublimesvn/proc.py", line 71, in get_wc_root
  File "./sublimesvn/proc.py", line 172, in find_wc_root
ProcessError
2013-02-25 16:10:09
Traceback (most recent call last):
  File "./sublimesvn/threads.py", line 18, in run_with_except_hook
  File "./sublimesvn/listeners.py", line 30, in run
  File "./sublimesvn/proc.py", line 71, in get_wc_root
  File "./sublimesvn/proc.py", line 172, in find_wc_root
ProcessError: <unprintable ProcessError object>
2013-02-25 18:28:44
Traceback (most recent call last):
  File "./sublimesvn/threads.py", line 18, in run_with_except_hook
  File "./sublimesvn/listeners.py", line 30, in run
  File "./sublimesvn/proc.py", line 71, in get_wc_root
  File "./sublimesvn/proc.py", line 172, in find_wc_root
ProcessError
2013-03-05 15:14:22
Traceback (most recent call last):
  File "./sublimesvn/threads.py", line 18, in run_with_except_hook
  File "./sublimesvn/listeners.py", line 30, in run
  File "./sublimesvn/proc.py", line 71, in get_wc_root
  File "./sublimesvn/proc.py", line 172, in find_wc_root
ProcessError: <unprintable ProcessError object>
2013-03-07 11:40:23
Traceback (most recent call last):
  File "./sublimesvn/threads.py", line 18, in run_with_except_hook
  File "./sublimesvn/proc.py", line 88, in run
ProcessError: <unprintable ProcessError object>
2013-03-07 11:40:23
Traceback (most recent call last):
  File "./sublimesvn/threads.py", line 18, in run_with_except_hook
  File "./sublimesvn/listeners.py", line 30, in run
  File "./sublimesvn/proc.py", line 71, in get_wc_root
  File "./sublimesvn/proc.py", line 172, in find_wc_root
ProcessError: <unprintable ProcessError object>
2013-03-08 18:19:59
Traceback (most recent call last):
  File "./sublimesvn/threads.py", line 18, in run_with_except_hook
  File "./sublimesvn/listeners.py", line 30, in run
  File "./sublimesvn/proc.py", line 71, in get_wc_root
  File "./sublimesvn/proc.py", line 172, in find_wc_root
ProcessError: <unprintable ProcessError object>
2013-03-08 18:20:01
Traceback (most recent call last):
  File "./sublimesvn/threads.py", line 18, in run_with_except_hook
  File "./sublimesvn/listeners.py", line 30, in run
  File "./sublimesvn/proc.py", line 71, in get_wc_root
  File "./sublimesvn/proc.py", line 172, in find_wc_root
ProcessError: <unprintable ProcessError object>
2013-03-13 10:31:51
Traceback (most recent call last):
  File "./sublimesvn/listeners.py", line 65, in rm
  File ".\shutil.py", line 221, in rmtree
  File ".\shutil.py", line 219, in rmtree
WindowsError: [Error 3] Le chemin daccès spécifié est introuvable: u'c:\\users\\stepha~1.vas\\appdata\\local\\temp\\sublime-svn-1363185057\\SVN'
2013-03-27 15:33:07
Traceback (most recent call last):
  File "./sublimesvn/threads.py", line 18, in run_with_except_hook
  File "./sublimesvn/proc.py", line 88, in run
ProcessError: <unprintable ProcessError object>
2013-04-03 13:21:09
Traceback (most recent call last):
  File "./sublimesvn/threads.py", line 18, in run_with_except_hook
  File "./sublimesvn/listeners.py", line 30, in run
  File "./sublimesvn/proc.py", line 71, in get_wc_root
  File "./sublimesvn/proc.py", line 172, in find_wc_root
ProcessError: <unprintable ProcessError object>
2013-04-03 13:21:11
Traceback (most recent call last):
  File "./sublimesvn/threads.py", line 18, in run_with_except_hook
  File "./sublimesvn/listeners.py", line 30, in run
  File "./sublimesvn/proc.py", line 71, in get_wc_root
  File "./sublimesvn/proc.py", line 172, in find_wc_root
ProcessError: <unprintable ProcessError object>
2013-04-03 13:21:11
Traceback (most recent call last):
  File "./sublimesvn/threads.py", line 18, in run_with_except_hook
  File "./sublimesvn/listeners.py", line 30, in run
  File "./sublimesvn/proc.py", line 71, in get_wc_root
  File "./sublimesvn/proc.py", line 172, in find_wc_root
ProcessError: <unprintable ProcessError object>
2013-04-03 13:21:13
Traceback (most recent call last):
  File "./sublimesvn/threads.py", line 18, in run_with_except_hook
  File "./sublimesvn/listeners.py", line 30, in run
  File "./sublimesvn/proc.py", line 71, in get_wc_root
  File "./sublimesvn/proc.py", line 172, in find_wc_root
ProcessError: <unprintable ProcessError object>
2013-04-03 16:11:31
Traceback (most recent call last):
  File "./sublimesvn/threads.py", line 18, in run_with_except_hook
  File "./sublimesvn/listeners.py", line 30, in run
  File "./sublimesvn/proc.py", line 71, in get_wc_root
  File "./sublimesvn/proc.py", line 172, in find_wc_root
ProcessError: svn: The path '.' appears to be part of a Subversion 1.7 or greater
working copy.  Please upgrade your Subversion client to use this
working copy.
2013-04-03 16:11:34
Traceback (most recent call last):
  File "./sublimesvn/threads.py", line 18, in run_with_except_hook
  File "./sublimesvn/listeners.py", line 30, in run
  File "./sublimesvn/proc.py", line 71, in get_wc_root
  File "./sublimesvn/proc.py", line 172, in find_wc_root
ProcessError: svn: The path '.' appears to be part of a Subversion 1.7 or greater
working copy.  Please upgrade your Subversion client to use this
working copy.
2013-04-03 16:11:37
Traceback (most recent call last):
  File "./sublimesvn/threads.py", line 18, in run_with_except_hook
  File "./sublimesvn/listeners.py", line 30, in run
  File "./sublimesvn/proc.py", line 71, in get_wc_root
  File "./sublimesvn/proc.py", line 172, in find_wc_root
ProcessError: svn: The path '.' appears to be part of a Subversion 1.7 or greater
working copy.  Please upgrade your Subversion client to use this
working copy.
2013-04-03 16:11:41
Traceback (most recent call last):
  File "./sublimesvn/threads.py", line 18, in run_with_except_hook
  File "./sublimesvn/listeners.py", line 30, in run
  File "./sublimesvn/proc.py", line 71, in get_wc_root
  File "./sublimesvn/proc.py", line 172, in find_wc_root
ProcessError: svn: The path '.' appears to be part of a Subversion 1.7 or greater
working copy.  Please upgrade your Subversion client to use this
working copy.
2013-04-03 16:11:47
Traceback (most recent call last):
  File "./sublimesvn/threads.py", line 18, in run_with_except_hook
  File "./sublimesvn/listeners.py", line 30, in run
  File "./sublimesvn/proc.py", line 71, in get_wc_root
  File "./sublimesvn/proc.py", line 172, in find_wc_root
ProcessError: svn: The path '.' appears to be part of a Subversion 1.7 or greater
working copy.  Please upgrade your Subversion client to use this
working copy.
2013-04-03 16:11:49
Traceback (most recent call last):
  File "./sublimesvn/threads.py", line 18, in run_with_except_hook
  File "./sublimesvn/listeners.py", line 30, in run
  File "./sublimesvn/proc.py", line 71, in get_wc_root
  File "./sublimesvn/proc.py", line 172, in find_wc_root
ProcessError: svn: The path '.' appears to be part of a Subversion 1.7 or greater
working copy.  Please upgrade your Subversion client to use this
working copy.
2013-04-03 16:12:00
Traceback (most recent call last):
  File "./sublimesvn/threads.py", line 18, in run_with_except_hook
  File "./sublimesvn/listeners.py", line 30, in run
  File "./sublimesvn/proc.py", line 71, in get_wc_root
  File "./sublimesvn/proc.py", line 172, in find_wc_root
ProcessError: svn: The path '.' appears to be part of a Subversion 1.7 or greater
working copy.  Please upgrade your Subversion client to use this
working copy.
2013-04-03 16:12:54
Traceback (most recent call last):
  File "./sublimesvn/threads.py", line 18, in run_with_except_hook
  File "./sublimesvn/listeners.py", line 30, in run
  File "./sublimesvn/proc.py", line 71, in get_wc_root
  File "./sublimesvn/proc.py", line 172, in find_wc_root
ProcessError: <unprintable ProcessError object>
2013-04-03 16:13:53
Traceback (most recent call last):
  File "./sublimesvn/threads.py", line 18, in run_with_except_hook
  File "./sublimesvn/proc.py", line 88, in run
ProcessError: <unprintable ProcessError object>
2013-04-03 17:52:03
Traceback (most recent call last):
  File "./sublimesvn/threads.py", line 18, in run_with_except_hook
  File "./sublimesvn/listeners.py", line 30, in run
  File "./sublimesvn/proc.py", line 71, in get_wc_root
  File "./sublimesvn/proc.py", line 172, in find_wc_root
ProcessError: svn: The path '.' appears to be part of a Subversion 1.7 or greater
working copy.  Please upgrade your Subversion client to use this
working copy.
2013-04-03 17:52:06
Traceback (most recent call last):
  File "./sublimesvn/threads.py", line 18, in run_with_except_hook
  File "./sublimesvn/listeners.py", line 30, in run
  File "./sublimesvn/proc.py", line 71, in get_wc_root
  File "./sublimesvn/proc.py", line 172, in find_wc_root
ProcessError: svn: The path '.' appears to be part of a Subversion 1.7 or greater
working copy.  Please upgrade your Subversion client to use this
working copy.
2013-04-03 17:52:08
Traceback (most recent call last):
  File "./sublimesvn/threads.py", line 18, in run_with_except_hook
  File "./sublimesvn/listeners.py", line 30, in run
  File "./sublimesvn/proc.py", line 71, in get_wc_root
  File "./sublimesvn/proc.py", line 172, in find_wc_root
ProcessError: svn: The path '.' appears to be part of a Subversion 1.7 or greater
working copy.  Please upgrade your Subversion client to use this
working copy.
2013-04-03 17:52:10
Traceback (most recent call last):
  File "./sublimesvn/threads.py", line 18, in run_with_except_hook
  File "./sublimesvn/listeners.py", line 30, in run
  File "./sublimesvn/proc.py", line 71, in get_wc_root
  File "./sublimesvn/proc.py", line 172, in find_wc_root
ProcessError: svn: The path '.' appears to be part of a Subversion 1.7 or greater
working copy.  Please upgrade your Subversion client to use this
working copy.
2013-04-03 17:52:13
Traceback (most recent call last):
  File "./sublimesvn/threads.py", line 18, in run_with_except_hook
  File "./sublimesvn/listeners.py", line 30, in run
  File "./sublimesvn/proc.py", line 71, in get_wc_root
  File "./sublimesvn/proc.py", line 172, in find_wc_root
ProcessError: svn: The path '.' appears to be part of a Subversion 1.7 or greater
working copy.  Please upgrade your Subversion client to use this
working copy.
2013-04-03 17:53:05
Traceback (most recent call last):
  File "./sublimesvn/threads.py", line 18, in run_with_except_hook
  File "./sublimesvn/listeners.py", line 30, in run
  File "./sublimesvn/proc.py", line 71, in get_wc_root
  File "./sublimesvn/proc.py", line 172, in find_wc_root
ProcessError: svn: The path '.' appears to be part of a Subversion 1.7 or greater
working copy.  Please upgrade your Subversion client to use this
working copy.
2013-04-03 19:22:05
Traceback (most recent call last):
  File "./sublimesvn/threads.py", line 18, in run_with_except_hook
  File "./sublimesvn/listeners.py", line 30, in run
  File "./sublimesvn/proc.py", line 71, in get_wc_root
  File "./sublimesvn/proc.py", line 172, in find_wc_root
ProcessError: svn: E155037: Previous operation has not finished; run 'cleanup' if it was interrupted
2013-05-03 14:23:41
Traceback (most recent call last):
  File "./sublimesvn/threads.py", line 18, in run_with_except_hook
  File "./sublimesvn/listeners.py", line 30, in run
  File "./sublimesvn/proc.py", line 71, in get_wc_root
  File "./sublimesvn/proc.py", line 155, in find_wc_root
  File "./sublimesvn/proc.py", line 973, in run
ProcessError: svn: E155010: The node 'X:\rc\website\trunk\web\doc\js\local\assets\css\external-small.png' was not found.
2013-05-03 14:23:45
Traceback (most recent call last):
  File "./sublimesvn/threads.py", line 18, in run_with_except_hook
  File "./sublimesvn/listeners.py", line 30, in run
  File "./sublimesvn/proc.py", line 71, in get_wc_root
  File "./sublimesvn/proc.py", line 155, in find_wc_root
  File "./sublimesvn/proc.py", line 973, in run
ProcessError: svn: E155010: The node 'X:\rc\website\trunk\web\doc\js\local\assets\css\external-small.png' was not found.
2013-05-03 14:23:49
Traceback (most recent call last):
  File "./sublimesvn/threads.py", line 18, in run_with_except_hook
  File "./sublimesvn/listeners.py", line 30, in run
  File "./sublimesvn/proc.py", line 71, in get_wc_root
  File "./sublimesvn/proc.py", line 155, in find_wc_root
  File "./sublimesvn/proc.py", line 973, in run
ProcessError: svn: E155010: The node 'X:\rc\website\trunk\web\doc\js\local\assets\css\external-small.png' was not found.
2013-05-03 14:23:53
Traceback (most recent call last):
  File "./sublimesvn/threads.py", line 18, in run_with_except_hook
  File "./sublimesvn/listeners.py", line 30, in run
  File "./sublimesvn/proc.py", line 71, in get_wc_root
  File "./sublimesvn/proc.py", line 155, in find_wc_root
  File "./sublimesvn/proc.py", line 973, in run
ProcessError: svn: E155010: The node 'X:\rc\website\trunk\web\doc\js\local\assets\css\external-small.png' was not found.
2013-05-03 14:23:57
Traceback (most recent call last):
  File "./sublimesvn/threads.py", line 18, in run_with_except_hook
  File "./sublimesvn/listeners.py", line 30, in run
  File "./sublimesvn/proc.py", line 71, in get_wc_root
  File "./sublimesvn/proc.py", line 155, in find_wc_root
  File "./sublimesvn/proc.py", line 973, in run
ProcessError: svn: E155010: The node 'X:\rc\website\trunk\web\doc\js\local\assets\css\external-small.png' was not found.
2013-05-03 14:24:00
Traceback (most recent call last):
  File "./sublimesvn/threads.py", line 18, in run_with_except_hook
  File "./sublimesvn/listeners.py", line 30, in run
  File "./sublimesvn/proc.py", line 71, in get_wc_root
  File "./sublimesvn/proc.py", line 155, in find_wc_root
  File "./sublimesvn/proc.py", line 973, in run
ProcessError: svn: E155010: The node 'X:\rc\website\trunk\web\doc\js\local\assets\css\external-small.png' was not found.
2013-05-03 14:36:37
Traceback (most recent call last):
  File "./sublimesvn/threads.py", line 18, in run_with_except_hook
  File "./sublimesvn/listeners.py", line 30, in run
  File "./sublimesvn/proc.py", line 71, in get_wc_root
  File "./sublimesvn/proc.py", line 155, in find_wc_root
  File "./sublimesvn/proc.py", line 973, in run
ProcessError: svn: E155010: The node 'X:\rc\website\trunk\web\doc\js\local\assets\css\external-small.png' was not found.
2013-05-03 14:39:58
Traceback (most recent call last):
  File "./sublimesvn/threads.py", line 18, in run_with_except_hook
  File "./sublimesvn/listeners.py", line 30, in run
  File "./sublimesvn/proc.py", line 71, in get_wc_root
  File "./sublimesvn/proc.py", line 155, in find_wc_root
  File "./sublimesvn/proc.py", line 973, in run
ProcessError: svn: E155010: The node 'X:\rc\website\trunk\web\doc\js\local\assets\css\external-small.png' was not found.
2013-05-03 14:40:12
Traceback (most recent call last):
  File "./sublimesvn/threads.py", line 18, in run_with_except_hook
  File "./sublimesvn/listeners.py", line 30, in run
  File "./sublimesvn/proc.py", line 71, in get_wc_root
  File "./sublimesvn/proc.py", line 155, in find_wc_root
  File "./sublimesvn/proc.py", line 973, in run
ProcessError: svn: E155010: The node 'X:\rc\website\trunk\web\doc\js\local\assets\css\external-small.png' was not found.
2013-05-03 15:19:11
Traceback (most recent call last):
  File "./sublimesvn/threads.py", line 18, in run_with_except_hook
  File "./sublimesvn/listeners.py", line 30, in run
  File "./sublimesvn/proc.py", line 71, in get_wc_root
  File "./sublimesvn/proc.py", line 155, in find_wc_root
  File "./sublimesvn/proc.py", line 973, in run
ProcessError: svn: E155010: The node 'X:\rc\website\trunk\web\doc\js\local\assets\css\external-small.png' was not found.
2013-05-03 15:19:15
Traceback (most recent call last):
  File "./sublimesvn/threads.py", line 18, in run_with_except_hook
  File "./sublimesvn/listeners.py", line 30, in run
  File "./sublimesvn/proc.py", line 71, in get_wc_root
  File "./sublimesvn/proc.py", line 155, in find_wc_root
  File "./sublimesvn/proc.py", line 973, in run
ProcessError: svn: E155010: The node 'X:\rc\website\trunk\web\doc\js\local\assets\css\external-small.png' was not found.
2013-05-03 15:19:25
Traceback (most recent call last):
  File "./sublimesvn/threads.py", line 18, in run_with_except_hook
  File "./sublimesvn/listeners.py", line 30, in run
  File "./sublimesvn/proc.py", line 71, in get_wc_root
  File "./sublimesvn/proc.py", line 155, in find_wc_root
  File "./sublimesvn/proc.py", line 973, in run
ProcessError: svn: E155010: The node 'X:\rc\website\trunk\web\doc\js\local\assets\css\external-small.png' was not found.
2013-05-03 15:19:30
Traceback (most recent call last):
  File "./sublimesvn/threads.py", line 18, in run_with_except_hook
  File "./sublimesvn/listeners.py", line 30, in run
  File "./sublimesvn/proc.py", line 71, in get_wc_root
  File "./sublimesvn/proc.py", line 155, in find_wc_root
  File "./sublimesvn/proc.py", line 973, in run
ProcessError: svn: E155010: The node 'X:\rc\website\trunk\web\doc\js\local\assets\css\external-small.png' was not found.
2013-05-03 15:19:35
Traceback (most recent call last):
  File "./sublimesvn/threads.py", line 18, in run_with_except_hook
  File "./sublimesvn/listeners.py", line 30, in run
  File "./sublimesvn/proc.py", line 71, in get_wc_root
  File "./sublimesvn/proc.py", line 155, in find_wc_root
  File "./sublimesvn/proc.py", line 973, in run
ProcessError: svn: E155010: The node 'X:\rc\website\trunk\web\doc\js\local\assets\css\external-small.png' was not found.
2013-05-03 15:19:37
Traceback (most recent call last):
  File "./sublimesvn/threads.py", line 18, in run_with_except_hook
  File "./sublimesvn/listeners.py", line 30, in run
  File "./sublimesvn/proc.py", line 71, in get_wc_root
  File "./sublimesvn/proc.py", line 155, in find_wc_root
  File "./sublimesvn/proc.py", line 973, in run
ProcessError: svn: E155010: The node 'X:\rc\website\trunk\web\doc\js\local\assets\css\external-small.png' was not found.
2013-05-03 15:19:45
Traceback (most recent call last):
  File "./sublimesvn/threads.py", line 18, in run_with_except_hook
  File "./sublimesvn/listeners.py", line 30, in run
  File "./sublimesvn/proc.py", line 71, in get_wc_root
  File "./sublimesvn/proc.py", line 155, in find_wc_root
  File "./sublimesvn/proc.py", line 973, in run
ProcessError: svn: E155010: The node 'X:\rc\website\trunk\web\doc\js\local\assets\css\external-small.png' was not found.
2013-05-03 15:22:33
Traceback (most recent call last):
  File "./sublimesvn/threads.py", line 18, in run_with_except_hook
  File "./sublimesvn/listeners.py", line 30, in run
  File "./sublimesvn/proc.py", line 71, in get_wc_root
  File "./sublimesvn/proc.py", line 155, in find_wc_root
  File "./sublimesvn/proc.py", line 973, in run
ProcessError: svn: E155010: The node 'X:\rc\website\trunk\web\doc\js\local\assets\css\external-small.png' was not found.
2013-05-03 15:22:36
Traceback (most recent call last):
  File "./sublimesvn/threads.py", line 18, in run_with_except_hook
  File "./sublimesvn/listeners.py", line 30, in run
  File "./sublimesvn/proc.py", line 71, in get_wc_root
  File "./sublimesvn/proc.py", line 155, in find_wc_root
  File "./sublimesvn/proc.py", line 973, in run
ProcessError: svn: E155010: The node 'X:\rc\website\trunk\web\doc\js\local\assets\css\external-small.png' was not found.
2013-05-03 15:22:56
Traceback (most recent call last):
  File "./sublimesvn/threads.py", line 18, in run_with_except_hook
  File "./sublimesvn/listeners.py", line 30, in run
  File "./sublimesvn/proc.py", line 71, in get_wc_root
  File "./sublimesvn/proc.py", line 155, in find_wc_root
  File "./sublimesvn/proc.py", line 973, in run
ProcessError: svn: E155010: The node 'X:\rc\website\trunk\web\doc\js\local\assets\css\external-small.png' was not found.
2013-05-03 15:22:59
Traceback (most recent call last):
  File "./sublimesvn/threads.py", line 18, in run_with_except_hook
  File "./sublimesvn/listeners.py", line 30, in run
  File "./sublimesvn/proc.py", line 71, in get_wc_root
  File "./sublimesvn/proc.py", line 155, in find_wc_root
  File "./sublimesvn/proc.py", line 973, in run
ProcessError: svn: E155010: The node 'X:\rc\website\trunk\web\doc\js\local\assets\css\external-small.png' was not found.
2013-05-03 15:23:29
Traceback (most recent call last):
  File "./sublimesvn/threads.py", line 18, in run_with_except_hook
  File "./sublimesvn/proc.py", line 88, in run
ProcessError: <unprintable ProcessError object>
2013-05-03 15:23:35
Traceback (most recent call last):
  File "./sublimesvn/threads.py", line 18, in run_with_except_hook
  File "./sublimesvn/proc.py", line 88, in run
ProcessError: <unprintable ProcessError object>
2013-05-03 15:24:31
Traceback (most recent call last):
  File "./sublimesvn/threads.py", line 18, in run_with_except_hook
  File "./sublimesvn/listeners.py", line 30, in run
  File "./sublimesvn/proc.py", line 71, in get_wc_root
  File "./sublimesvn/proc.py", line 155, in find_wc_root
  File "./sublimesvn/proc.py", line 973, in run
ProcessError: svn: E155010: The node 'X:\rc\website\trunk\web\doc\js\local\assets\css\external-small.png' was not found.
2013-05-03 15:28:01
Traceback (most recent call last):
  File "./sublimesvn/threads.py", line 18, in run_with_except_hook
  File "./sublimesvn/listeners.py", line 30, in run
  File "./sublimesvn/proc.py", line 71, in get_wc_root
  File "./sublimesvn/proc.py", line 155, in find_wc_root
  File "./sublimesvn/proc.py", line 973, in run
ProcessError: svn: E155010: The node 'X:\rc\website\trunk\web\doc\js\local\assets\css\external-small.png' was not found.
2013-05-03 15:28:04
Traceback (most recent call last):
  File "./sublimesvn/threads.py", line 18, in run_with_except_hook
  File "./sublimesvn/listeners.py", line 30, in run
  File "./sublimesvn/proc.py", line 71, in get_wc_root
  File "./sublimesvn/proc.py", line 155, in find_wc_root
  File "./sublimesvn/proc.py", line 973, in run
ProcessError: svn: E155010: The node 'X:\rc\website\trunk\web\doc\js\local\assets\css\external-small.png' was not found.
2013-05-03 15:28:08
Traceback (most recent call last):
  File "./sublimesvn/threads.py", line 18, in run_with_except_hook
  File "./sublimesvn/listeners.py", line 30, in run
  File "./sublimesvn/proc.py", line 71, in get_wc_root
  File "./sublimesvn/proc.py", line 155, in find_wc_root
  File "./sublimesvn/proc.py", line 973, in run
ProcessError: svn: E155010: The node 'X:\rc\website\trunk\web\doc\js\local\assets\css\external-small.png' was not found.
2013-05-03 15:31:03
Traceback (most recent call last):
  File "./sublimesvn/threads.py", line 18, in run_with_except_hook
  File "./sublimesvn/listeners.py", line 30, in run
  File "./sublimesvn/proc.py", line 71, in get_wc_root
  File "./sublimesvn/proc.py", line 155, in find_wc_root
  File "./sublimesvn/proc.py", line 973, in run
ProcessError: svn: E155010: The node 'X:\rc\website\trunk\web\doc\js\local\assets\css\external-small.png' was not found.
2013-05-03 15:31:07
Traceback (most recent call last):
  File "./sublimesvn/threads.py", line 18, in run_with_except_hook
  File "./sublimesvn/listeners.py", line 30, in run
  File "./sublimesvn/proc.py", line 71, in get_wc_root
  File "./sublimesvn/proc.py", line 155, in find_wc_root
  File "./sublimesvn/proc.py", line 973, in run
ProcessError: svn: E155010: The node 'X:\rc\website\trunk\web\doc\js\local\assets\css\external-small.png' was not found.
2013-05-03 15:31:10
Traceback (most recent call last):
  File "./sublimesvn/threads.py", line 18, in run_with_except_hook
  File "./sublimesvn/listeners.py", line 30, in run
  File "./sublimesvn/proc.py", line 71, in get_wc_root
  File "./sublimesvn/proc.py", line 155, in find_wc_root
  File "./sublimesvn/proc.py", line 973, in run
ProcessError: svn: E155010: The node 'X:\rc\website\trunk\web\doc\js\local\assets\css\external-small.png' was not found.
2013-05-03 15:31:16
Traceback (most recent call last):
  File "./sublimesvn/threads.py", line 18, in run_with_except_hook
  File "./sublimesvn/listeners.py", line 30, in run
  File "./sublimesvn/proc.py", line 71, in get_wc_root
  File "./sublimesvn/proc.py", line 155, in find_wc_root
  File "./sublimesvn/proc.py", line 973, in run
ProcessError: svn: E200033: sqlite: database is locked
svn: E200033: sqlite: database is locked
2013-05-03 15:31:16
Traceback (most recent call last):
  File "./sublimesvn/threads.py", line 18, in run_with_except_hook
  File "./sublimesvn/listeners.py", line 30, in run
  File "./sublimesvn/proc.py", line 71, in get_wc_root
  File "./sublimesvn/proc.py", line 155, in find_wc_root
  File "./sublimesvn/proc.py", line 973, in run
ProcessError: svn: E200033: sqlite: database is locked
svn: E200033: sqlite: database is locked
2013-05-03 15:31:16
Traceback (most recent call last):
  File "./sublimesvn/threads.py", line 18, in run_with_except_hook
  File "./sublimesvn/listeners.py", line 30, in run
  File "./sublimesvn/proc.py", line 71, in get_wc_root
  File "./sublimesvn/proc.py", line 155, in find_wc_root
  File "./sublimesvn/proc.py", line 973, in run
ProcessError: svn: E155010: The node 'X:\rc\website\trunk\web\doc\js\local\assets\css\external-small.png' was not found.
2013-06-10 21:53:28
Traceback (most recent call last):
  File "./sublimesvn/threads.py", line 18, in run_with_except_hook
  File "./sublimesvn/status.py", line 528, in run
  File "./sublimesvn/proc.py", line 895, in run
  File "./sublimesvn/proc.py", line 355, in __init__
  File "./sublimesvn/proc.py", line 377, in open
TypeError: 'NoneType' object is unsubscriptable
2013-07-19 16:56:53
Traceback (most recent call last):
  File "./sublimesvn/threads.py", line 18, in run_with_except_hook
  File "./sublimesvn/threads.py", line 89, in run
  File "./sublimesvn/commands.py", line 1149, in do_edit_message
  File ".\os.py", line 157, in makedirs
WindowsError: [Error 183] Impossible de créer un fichier déjà existant: 'c:\\users\\stepha~1.vas\\appdata\\local\\temp\\sublime-svn-1374267409'
